{"created": 1720632100.363553, "duration": 44.07778477668762, "exitcode": 1, "root": "C:\\Users\\Administrator\\Automation\\Tests", "environment": {}, "summary": {"failed": 1, "total": 1, "collected": 1}, "collectors": [{"nodeid": "", "outcome": "passed", "result": [{"nodeid": "test_AddMoney.py", "type": "Module"}]}, {"nodeid": "test_AddMoney.py", "outcome": "passed", "result": [{"nodeid": "test_AddMoney.py::test_add_money", "type": "Coroutine", "lineno": 7}]}], "tests": [{"nodeid": "test_AddMoney.py::test_add_money", "lineno": 7, "outcome": "failed", "keywords": ["test_add_money", "qa", "asyncio", "regression", "pytestmark", "test_AddMoney.py", "__init__.py", "Tests"], "setup": {"duration": 0.0029910001903772354, "outcome": "passed"}, "call": {"duration": 43.64668839983642, "outcome": "failed", "crash": {"path": "C:\\Users\\Administrator\\AppData\\Local\\Programs\\Python\\Python311\\Lib\\site-packages\\playwright\\_impl\\_connection.py", "lineno": 100, "message": "playwright._impl._errors.TimeoutError: Timeout 30000ms exceeded."}, "traceback": [{"path": "test_AddMoney.py", "lineno": 50, "message": ""}, {"path": "..\\..\\AppData\\Local\\Programs\\Python\\Python311\\Lib\\site-packages\\playwright\\async_api\\_generated.py", "lineno": 15706, "message": "in click"}, {"path": "..\\..\\AppData\\Local\\Programs\\Python\\Python311\\Lib\\site-packages\\playwright\\_impl\\_locator.py", "lineno": 159, "message": "in click"}, {"path": "..\\..\\AppData\\Local\\Programs\\Python\\Python311\\Lib\\site-packages\\playwright\\_impl\\_frame.py", "lineno": 484, "message": "in click"}, {"path": "..\\..\\AppData\\Local\\Programs\\Python\\Python311\\Lib\\site-packages\\playwright\\_impl\\_connection.py", "lineno": 62, "message": "in send"}, {"path": "..\\..\\AppData\\Local\\Programs\\Python\\Python311\\Lib\\site-packages\\playwright\\_impl\\_connection.py", "lineno": 492, "message": "in wrap_api_call"}, {"path": "..\\..\\AppData\\Local\\Programs\\Python\\Python311\\Lib\\site-packages\\playwright\\_impl\\_connection.py", "lineno": 100, "message": "TimeoutError"}], "stdout": "<Page url='https://okoora-qa-front2023.azurewebsites.net/login'>\nhttps://okoora-qa-api2023.azurewebsites.net/api/Authentication/RefreshToken?refreshToken=undefined 400 {\n  \"apiErrorCode\": 1500,\n  \"apiErrorMessage\": [\n    \"The value 'undefined' is not valid.\"\n  ]\n}\nWaiting for response...\nResponse received.\nWaiting for response...\nResponse received.\nhttps://okoora-qa-api2023.azurewebsites.net/api/Kyc/GetSumSubAccessToken 400 {\n  \"apiErrorCode\": 3108,\n  \"apiErrorMessage\": [\n    \"Un Used By Configure\"\n  ]\n}\n", "log": [{"name": "asyncio", "msg": "Exception in callback AsyncIOEventEmitter._emit_run.<locals>.callback(<Task finishe... 1 (char 0)')>) at C:\\Users\\Administrator\\AppData\\Local\\Programs\\Python\\Python311\\Lib\\site-packages\\pyee\\asyncio.py:69\nhandle: <Handle AsyncIOEventEmitter._emit_run.<locals>.callback(<Task finishe... 1 (char 0)')>) at C:\\Users\\Administrator\\AppData\\Local\\Programs\\Python\\Python311\\Lib\\site-packages\\pyee\\asyncio.py:69>", "args": null, "levelname": "ERROR", "levelno": 40, "pathname": "C:\\Users\\Administrator\\AppData\\Local\\Programs\\Python\\Python311\\Lib\\asyncio\\base_events.py", "filename": "base_events.py", "module": "base_events", "exc_info": null, "exc_text": "Traceback (most recent call last):\n  File \"C:\\Users\\Administrator\\AppData\\Local\\Programs\\Python\\Python311\\Lib\\asyncio\\events.py\", line 80, in _run\n    self._context.run(self._callback, *self._args)\n  File \"C:\\Users\\Administrator\\AppData\\Local\\Programs\\Python\\Python311\\Lib\\site-packages\\pyee\\asyncio.py\", line 77, in callback\n    self.emit(\"error\", exc)\n  File \"C:\\Users\\Administrator\\AppData\\Local\\Programs\\Python\\Python311\\Lib\\site-packages\\pyee\\base.py\", line 211, in emit\n    self._emit_handle_potential_error(event, args[0] if args else None)\n  File \"C:\\Users\\Administrator\\AppData\\Local\\Programs\\Python\\Python311\\Lib\\site-packages\\pyee\\base.py\", line 169, in _emit_handle_potential_error\n    raise error\n  File \"C:\\Users\\Administrator\\Automation\\Tests\\test_AddMoney.py\", line 34, in on_response\n    result = await response.json()\n             ^^^^^^^^^^^^^^^^^^^^^\n  File \"C:\\Users\\Administrator\\AppData\\Local\\Programs\\Python\\Python311\\Lib\\site-packages\\playwright\\async_api\\_generated.py\", line 636, in json\n    return mapping.from_maybe_impl(await self._impl_obj.json())\n                                   ^^^^^^^^^^^^^^^^^^^^^^^^^^^\n  File \"C:\\Users\\Administrator\\AppData\\Local\\Programs\\Python\\Python311\\Lib\\site-packages\\playwright\\_impl\\_network.py\", line 590, in json\n    return json.loads(await self.text())\n           ^^^^^^^^^^^^^^^^^^^^^^^^^^^^^\n  File \"C:\\Users\\Administrator\\AppData\\Local\\Programs\\Python\\Python311\\Lib\\json\\__init__.py\", line 346, in loads\n    return _default_decoder.decode(s)\n           ^^^^^^^^^^^^^^^^^^^^^^^^^^\n  File \"C:\\Users\\Administrator\\AppData\\Local\\Programs\\Python\\Python311\\Lib\\json\\decoder.py\", line 337, in decode\n    obj, end = self.raw_decode(s, idx=_w(s, 0).end())\n               ^^^^^^^^^^^^^^^^^^^^^^^^^^^^^^^^^^^^^^\n  File \"C:\\Users\\Administrator\\AppData\\Local\\Programs\\Python\\Python311\\Lib\\json\\decoder.py\", line 355, in raw_decode\n    raise JSONDecodeError(\"Expecting value\", s, err.value) from None\njson.decoder.JSONDecodeError: Expecting value: line 1 column 1 (char 0)", "stack_info": null, "lineno": 1757, "funcName": "default_exception_handler", "created": 1720632068.998236, "msecs": 998.0, "relativeCreated": 13884.000539779663, "thread": 5872, "threadName": "MainThread", "processName": "MainProcess", "process": 8348}, {"name": "asyncio", "msg": "Exception in callback AsyncIOEventEmitter._emit_run.<locals>.callback(<Task finishe... 1 (char 0)')>) at C:\\Users\\Administrator\\AppData\\Local\\Programs\\Python\\Python311\\Lib\\site-packages\\pyee\\asyncio.py:69\nhandle: <Handle AsyncIOEventEmitter._emit_run.<locals>.callback(<Task finishe... 1 (char 0)')>) at C:\\Users\\Administrator\\AppData\\Local\\Programs\\Python\\Python311\\Lib\\site-packages\\pyee\\asyncio.py:69>", "args": null, "levelname": "ERROR", "levelno": 40, "pathname": "C:\\Users\\Administrator\\AppData\\Local\\Programs\\Python\\Python311\\Lib\\asyncio\\base_events.py", "filename": "base_events.py", "module": "base_events", "exc_info": null, "exc_text": "Traceback (most recent call last):\n  File \"C:\\Users\\Administrator\\AppData\\Local\\Programs\\Python\\Python311\\Lib\\asyncio\\events.py\", line 80, in _run\n    self._context.run(self._callback, *self._args)\n  File \"C:\\Users\\Administrator\\AppData\\Local\\Programs\\Python\\Python311\\Lib\\site-packages\\pyee\\asyncio.py\", line 77, in callback\n    self.emit(\"error\", exc)\n  File \"C:\\Users\\Administrator\\AppData\\Local\\Programs\\Python\\Python311\\Lib\\site-packages\\pyee\\base.py\", line 211, in emit\n    self._emit_handle_potential_error(event, args[0] if args else None)\n  File \"C:\\Users\\Administrator\\AppData\\Local\\Programs\\Python\\Python311\\Lib\\site-packages\\pyee\\base.py\", line 169, in _emit_handle_potential_error\n    raise error\n  File \"C:\\Users\\Administrator\\Automation\\Tests\\test_AddMoney.py\", line 34, in on_response\n    result = await response.json()\n             ^^^^^^^^^^^^^^^^^^^^^\n  File \"C:\\Users\\Administrator\\AppData\\Local\\Programs\\Python\\Python311\\Lib\\site-packages\\playwright\\async_api\\_generated.py\", line 636, in json\n    return mapping.from_maybe_impl(await self._impl_obj.json())\n                                   ^^^^^^^^^^^^^^^^^^^^^^^^^^^\n  File \"C:\\Users\\Administrator\\AppData\\Local\\Programs\\Python\\Python311\\Lib\\site-packages\\playwright\\_impl\\_network.py\", line 590, in json\n    return json.loads(await self.text())\n           ^^^^^^^^^^^^^^^^^^^^^^^^^^^^^\n  File \"C:\\Users\\Administrator\\AppData\\Local\\Programs\\Python\\Python311\\Lib\\json\\__init__.py\", line 346, in loads\n    return _default_decoder.decode(s)\n           ^^^^^^^^^^^^^^^^^^^^^^^^^^\n  File \"C:\\Users\\Administrator\\AppData\\Local\\Programs\\Python\\Python311\\Lib\\json\\decoder.py\", line 337, in decode\n    obj, end = self.raw_decode(s, idx=_w(s, 0).end())\n               ^^^^^^^^^^^^^^^^^^^^^^^^^^^^^^^^^^^^^^\n  File \"C:\\Users\\Administrator\\AppData\\Local\\Programs\\Python\\Python311\\Lib\\json\\decoder.py\", line 355, in raw_decode\n    raise JSONDecodeError(\"Expecting value\", s, err.value) from None\njson.decoder.JSONDecodeError: Expecting value: line 1 column 1 (char 0)", "stack_info": null, "lineno": 1757, "funcName": "default_exception_handler", "created": 1720632069.0958817, "msecs": 95.0, "relativeCreated": 13981.646299362183, "thread": 5872, "threadName": "MainThread", "processName": "MainProcess", "process": 8348}, {"name": "asyncio", "msg": "Exception in callback AsyncIOEventEmitter._emit_run.<locals>.callback(<Task finishe... identifier')>) at C:\\Users\\Administrator\\AppData\\Local\\Programs\\Python\\Python311\\Lib\\site-packages\\pyee\\asyncio.py:69\nhandle: <Handle AsyncIOEventEmitter._emit_run.<locals>.callback(<Task finishe... identifier')>) at C:\\Users\\Administrator\\AppData\\Local\\Programs\\Python\\Python311\\Lib\\site-packages\\pyee\\asyncio.py:69>", "args": null, "levelname": "ERROR", "levelno": 40, "pathname": "C:\\Users\\Administrator\\AppData\\Local\\Programs\\Python\\Python311\\Lib\\asyncio\\base_events.py", "filename": "base_events.py", "module": "base_events", "exc_info": null, "exc_text": "Traceback (most recent call last):\n  File \"C:\\Users\\Administrator\\AppData\\Local\\Programs\\Python\\Python311\\Lib\\asyncio\\events.py\", line 80, in _run\n    self._context.run(self._callback, *self._args)\n  File \"C:\\Users\\Administrator\\AppData\\Local\\Programs\\Python\\Python311\\Lib\\site-packages\\pyee\\asyncio.py\", line 77, in callback\n    self.emit(\"error\", exc)\n  File \"C:\\Users\\Administrator\\AppData\\Local\\Programs\\Python\\Python311\\Lib\\site-packages\\pyee\\base.py\", line 211, in emit\n    self._emit_handle_potential_error(event, args[0] if args else None)\n  File \"C:\\Users\\Administrator\\AppData\\Local\\Programs\\Python\\Python311\\Lib\\site-packages\\pyee\\base.py\", line 169, in _emit_handle_potential_error\n    raise error\n  File \"C:\\Users\\Administrator\\Automation\\Tests\\test_AddMoney.py\", line 34, in on_response\n    result = await response.json()\n             ^^^^^^^^^^^^^^^^^^^^^\n  File \"C:\\Users\\Administrator\\AppData\\Local\\Programs\\Python\\Python311\\Lib\\site-packages\\playwright\\async_api\\_generated.py\", line 636, in json\n    return mapping.from_maybe_impl(await self._impl_obj.json())\n                                   ^^^^^^^^^^^^^^^^^^^^^^^^^^^\n  File \"C:\\Users\\Administrator\\AppData\\Local\\Programs\\Python\\Python311\\Lib\\site-packages\\playwright\\_impl\\_network.py\", line 590, in json\n    return json.loads(await self.text())\n                      ^^^^^^^^^^^^^^^^^\n  File \"C:\\Users\\Administrator\\AppData\\Local\\Programs\\Python\\Python311\\Lib\\site-packages\\playwright\\_impl\\_network.py\", line 586, in text\n    content = await self.body()\n              ^^^^^^^^^^^^^^^^^\n  File \"C:\\Users\\Administrator\\AppData\\Local\\Programs\\Python\\Python311\\Lib\\site-packages\\playwright\\_impl\\_network.py\", line 582, in body\n    binary = await self._channel.send(\"body\")\n             ^^^^^^^^^^^^^^^^^^^^^^^^^^^^^^^^\n  File \"C:\\Users\\Administrator\\AppData\\Local\\Programs\\Python\\Python311\\Lib\\site-packages\\playwright\\_impl\\_connection.py\", line 62, in send\n    return await self._connection.wrap_api_call(\n           ^^^^^^^^^^^^^^^^^^^^^^^^^^^^^^^^^^^^^\n  File \"C:\\Users\\Administrator\\AppData\\Local\\Programs\\Python\\Python311\\Lib\\site-packages\\playwright\\_impl\\_connection.py\", line 492, in wrap_api_call\n    return await cb()\n           ^^^^^^^^^^\n  File \"C:\\Users\\Administrator\\AppData\\Local\\Programs\\Python\\Python311\\Lib\\site-packages\\playwright\\_impl\\_connection.py\", line 100, in inner_send\n    result = next(iter(done)).result()\n             ^^^^^^^^^^^^^^^^^^^^^^^^^\nplaywright._impl._errors.Error: Protocol error (Network.getResponseBody): No data found for resource with given identifier", "stack_info": null, "lineno": 1757, "funcName": "default_exception_handler", "created": 1720632074.511824, "msecs": 511.0, "relativeCreated": 19397.58849143982, "thread": 5872, "threadName": "MainThread", "processName": "MainProcess", "process": 8348}, {"name": "asyncio", "msg": "Exception in callback AsyncIOEventEmitter._emit_run.<locals>.callback(<Task finishe... 1 (char 0)')>) at C:\\Users\\Administrator\\AppData\\Local\\Programs\\Python\\Python311\\Lib\\site-packages\\pyee\\asyncio.py:69\nhandle: <Handle AsyncIOEventEmitter._emit_run.<locals>.callback(<Task finishe... 1 (char 0)')>) at C:\\Users\\Administrator\\AppData\\Local\\Programs\\Python\\Python311\\Lib\\site-packages\\pyee\\asyncio.py:69>", "args": null, "levelname": "ERROR", "levelno": 40, "pathname": "C:\\Users\\Administrator\\AppData\\Local\\Programs\\Python\\Python311\\Lib\\asyncio\\base_events.py", "filename": "base_events.py", "module": "base_events", "exc_info": null, "exc_text": "Traceback (most recent call last):\n  File \"C:\\Users\\Administrator\\AppData\\Local\\Programs\\Python\\Python311\\Lib\\asyncio\\events.py\", line 80, in _run\n    self._context.run(self._callback, *self._args)\n  File \"C:\\Users\\Administrator\\AppData\\Local\\Programs\\Python\\Python311\\Lib\\site-packages\\pyee\\asyncio.py\", line 77, in callback\n    self.emit(\"error\", exc)\n  File \"C:\\Users\\Administrator\\AppData\\Local\\Programs\\Python\\Python311\\Lib\\site-packages\\pyee\\base.py\", line 211, in emit\n    self._emit_handle_potential_error(event, args[0] if args else None)\n  File \"C:\\Users\\Administrator\\AppData\\Local\\Programs\\Python\\Python311\\Lib\\site-packages\\pyee\\base.py\", line 169, in _emit_handle_potential_error\n    raise error\n  File \"C:\\Users\\Administrator\\Automation\\Tests\\test_AddMoney.py\", line 34, in on_response\n    result = await response.json()\n             ^^^^^^^^^^^^^^^^^^^^^\n  File \"C:\\Users\\Administrator\\AppData\\Local\\Programs\\Python\\Python311\\Lib\\site-packages\\playwright\\async_api\\_generated.py\", line 636, in json\n    return mapping.from_maybe_impl(await self._impl_obj.json())\n                                   ^^^^^^^^^^^^^^^^^^^^^^^^^^^\n  File \"C:\\Users\\Administrator\\AppData\\Local\\Programs\\Python\\Python311\\Lib\\site-packages\\playwright\\_impl\\_network.py\", line 590, in json\n    return json.loads(await self.text())\n           ^^^^^^^^^^^^^^^^^^^^^^^^^^^^^\n  File \"C:\\Users\\Administrator\\AppData\\Local\\Programs\\Python\\Python311\\Lib\\json\\__init__.py\", line 346, in loads\n    return _default_decoder.decode(s)\n           ^^^^^^^^^^^^^^^^^^^^^^^^^^\n  File \"C:\\Users\\Administrator\\AppData\\Local\\Programs\\Python\\Python311\\Lib\\json\\decoder.py\", line 337, in decode\n    obj, end = self.raw_decode(s, idx=_w(s, 0).end())\n               ^^^^^^^^^^^^^^^^^^^^^^^^^^^^^^^^^^^^^^\n  File \"C:\\Users\\Administrator\\AppData\\Local\\Programs\\Python\\Python311\\Lib\\json\\decoder.py\", line 355, in raw_decode\n    raise JSONDecodeError(\"Expecting value\", s, err.value) from None\njson.decoder.JSONDecodeError: Expecting value: line 1 column 1 (char 0)", "stack_info": null, "lineno": 1757, "funcName": "default_exception_handler", "created": 1720632081.799163, "msecs": 799.0, "relativeCreated": 26684.927701950073, "thread": 5872, "threadName": "MainThread", "processName": "MainProcess", "process": 8348}, {"name": "asyncio", "msg": "Exception in callback AsyncIOEventEmitter._emit_run.<locals>.callback(<Task finishe... 1 (char 0)')>) at C:\\Users\\Administrator\\AppData\\Local\\Programs\\Python\\Python311\\Lib\\site-packages\\pyee\\asyncio.py:69\nhandle: <Handle AsyncIOEventEmitter._emit_run.<locals>.callback(<Task finishe... 1 (char 0)')>) at C:\\Users\\Administrator\\AppData\\Local\\Programs\\Python\\Python311\\Lib\\site-packages\\pyee\\asyncio.py:69>", "args": null, "levelname": "ERROR", "levelno": 40, "pathname": "C:\\Users\\Administrator\\AppData\\Local\\Programs\\Python\\Python311\\Lib\\asyncio\\base_events.py", "filename": "base_events.py", "module": "base_events", "exc_info": null, "exc_text": "Traceback (most recent call last):\n  File \"C:\\Users\\Administrator\\AppData\\Local\\Programs\\Python\\Python311\\Lib\\asyncio\\events.py\", line 80, in _run\n    self._context.run(self._callback, *self._args)\n  File \"C:\\Users\\Administrator\\AppData\\Local\\Programs\\Python\\Python311\\Lib\\site-packages\\pyee\\asyncio.py\", line 77, in callback\n    self.emit(\"error\", exc)\n  File \"C:\\Users\\Administrator\\AppData\\Local\\Programs\\Python\\Python311\\Lib\\site-packages\\pyee\\base.py\", line 211, in emit\n    self._emit_handle_potential_error(event, args[0] if args else None)\n  File \"C:\\Users\\Administrator\\AppData\\Local\\Programs\\Python\\Python311\\Lib\\site-packages\\pyee\\base.py\", line 169, in _emit_handle_potential_error\n    raise error\n  File \"C:\\Users\\Administrator\\Automation\\Tests\\test_AddMoney.py\", line 34, in on_response\n    result = await response.json()\n             ^^^^^^^^^^^^^^^^^^^^^\n  File \"C:\\Users\\Administrator\\AppData\\Local\\Programs\\Python\\Python311\\Lib\\site-packages\\playwright\\async_api\\_generated.py\", line 636, in json\n    return mapping.from_maybe_impl(await self._impl_obj.json())\n                                   ^^^^^^^^^^^^^^^^^^^^^^^^^^^\n  File \"C:\\Users\\Administrator\\AppData\\Local\\Programs\\Python\\Python311\\Lib\\site-packages\\playwright\\_impl\\_network.py\", line 590, in json\n    return json.loads(await self.text())\n           ^^^^^^^^^^^^^^^^^^^^^^^^^^^^^\n  File \"C:\\Users\\Administrator\\AppData\\Local\\Programs\\Python\\Python311\\Lib\\json\\__init__.py\", line 346, in loads\n    return _default_decoder.decode(s)\n           ^^^^^^^^^^^^^^^^^^^^^^^^^^\n  File \"C:\\Users\\Administrator\\AppData\\Local\\Programs\\Python\\Python311\\Lib\\json\\decoder.py\", line 337, in decode\n    obj, end = self.raw_decode(s, idx=_w(s, 0).end())\n               ^^^^^^^^^^^^^^^^^^^^^^^^^^^^^^^^^^^^^^\n  File \"C:\\Users\\Administrator\\AppData\\Local\\Programs\\Python\\Python311\\Lib\\json\\decoder.py\", line 355, in raw_decode\n    raise JSONDecodeError(\"Expecting value\", s, err.value) from None\njson.decoder.JSONDecodeError: Expecting value: line 1 column 1 (char 0)", "stack_info": null, "lineno": 1757, "funcName": "default_exception_handler", "created": 1720632081.8001637, "msecs": 800.0, "relativeCreated": 26685.928344726562, "thread": 5872, "threadName": "MainThread", "processName": "MainProcess", "process": 8348}, {"name": "asyncio", "msg": "Exception in callback AsyncIOEventEmitter._emit_run.<locals>.callback(<Task finishe... 1 (char 0)')>) at C:\\Users\\Administrator\\AppData\\Local\\Programs\\Python\\Python311\\Lib\\site-packages\\pyee\\asyncio.py:69\nhandle: <Handle AsyncIOEventEmitter._emit_run.<locals>.callback(<Task finishe... 1 (char 0)')>) at C:\\Users\\Administrator\\AppData\\Local\\Programs\\Python\\Python311\\Lib\\site-packages\\pyee\\asyncio.py:69>", "args": null, "levelname": "ERROR", "levelno": 40, "pathname": "C:\\Users\\Administrator\\AppData\\Local\\Programs\\Python\\Python311\\Lib\\asyncio\\base_events.py", "filename": "base_events.py", "module": "base_events", "exc_info": null, "exc_text": "Traceback (most recent call last):\n  File \"C:\\Users\\Administrator\\AppData\\Local\\Programs\\Python\\Python311\\Lib\\asyncio\\events.py\", line 80, in _run\n    self._context.run(self._callback, *self._args)\n  File \"C:\\Users\\Administrator\\AppData\\Local\\Programs\\Python\\Python311\\Lib\\site-packages\\pyee\\asyncio.py\", line 77, in callback\n    self.emit(\"error\", exc)\n  File \"C:\\Users\\Administrator\\AppData\\Local\\Programs\\Python\\Python311\\Lib\\site-packages\\pyee\\base.py\", line 211, in emit\n    self._emit_handle_potential_error(event, args[0] if args else None)\n  File \"C:\\Users\\Administrator\\AppData\\Local\\Programs\\Python\\Python311\\Lib\\site-packages\\pyee\\base.py\", line 169, in _emit_handle_potential_error\n    raise error\n  File \"C:\\Users\\Administrator\\Automation\\Tests\\test_AddMoney.py\", line 34, in on_response\n    result = await response.json()\n             ^^^^^^^^^^^^^^^^^^^^^\n  File \"C:\\Users\\Administrator\\AppData\\Local\\Programs\\Python\\Python311\\Lib\\site-packages\\playwright\\async_api\\_generated.py\", line 636, in json\n    return mapping.from_maybe_impl(await self._impl_obj.json())\n                                   ^^^^^^^^^^^^^^^^^^^^^^^^^^^\n  File \"C:\\Users\\Administrator\\AppData\\Local\\Programs\\Python\\Python311\\Lib\\site-packages\\playwright\\_impl\\_network.py\", line 590, in json\n    return json.loads(await self.text())\n           ^^^^^^^^^^^^^^^^^^^^^^^^^^^^^\n  File \"C:\\Users\\Administrator\\AppData\\Local\\Programs\\Python\\Python311\\Lib\\json\\__init__.py\", line 346, in loads\n    return _default_decoder.decode(s)\n           ^^^^^^^^^^^^^^^^^^^^^^^^^^\n  File \"C:\\Users\\Administrator\\AppData\\Local\\Programs\\Python\\Python311\\Lib\\json\\decoder.py\", line 337, in decode\n    obj, end = self.raw_decode(s, idx=_w(s, 0).end())\n               ^^^^^^^^^^^^^^^^^^^^^^^^^^^^^^^^^^^^^^\n  File \"C:\\Users\\Administrator\\AppData\\Local\\Programs\\Python\\Python311\\Lib\\json\\decoder.py\", line 355, in raw_decode\n    raise JSONDecodeError(\"Expecting value\", s, err.value) from None\njson.decoder.JSONDecodeError: Expecting value: line 1 column 1 (char 0)", "stack_info": null, "lineno": 1757, "funcName": "default_exception_handler", "created": 1720632081.8028994, "msecs": 802.0, "relativeCreated": 26688.663959503174, "thread": 5872, "threadName": "MainThread", "processName": "MainProcess", "process": 8348}, {"name": "asyncio", "msg": "Exception in callback AsyncIOEventEmitter._emit_run.<locals>.callback(<Task finishe... 1 (char 0)')>) at C:\\Users\\Administrator\\AppData\\Local\\Programs\\Python\\Python311\\Lib\\site-packages\\pyee\\asyncio.py:69\nhandle: <Handle AsyncIOEventEmitter._emit_run.<locals>.callback(<Task finishe... 1 (char 0)')>) at C:\\Users\\Administrator\\AppData\\Local\\Programs\\Python\\Python311\\Lib\\site-packages\\pyee\\asyncio.py:69>", "args": null, "levelname": "ERROR", "levelno": 40, "pathname": "C:\\Users\\Administrator\\AppData\\Local\\Programs\\Python\\Python311\\Lib\\asyncio\\base_events.py", "filename": "base_events.py", "module": "base_events", "exc_info": null, "exc_text": "Traceback (most recent call last):\n  File \"C:\\Users\\Administrator\\AppData\\Local\\Programs\\Python\\Python311\\Lib\\asyncio\\events.py\", line 80, in _run\n    self._context.run(self._callback, *self._args)\n  File \"C:\\Users\\Administrator\\AppData\\Local\\Programs\\Python\\Python311\\Lib\\site-packages\\pyee\\asyncio.py\", line 77, in callback\n    self.emit(\"error\", exc)\n  File \"C:\\Users\\Administrator\\AppData\\Local\\Programs\\Python\\Python311\\Lib\\site-packages\\pyee\\base.py\", line 211, in emit\n    self._emit_handle_potential_error(event, args[0] if args else None)\n  File \"C:\\Users\\Administrator\\AppData\\Local\\Programs\\Python\\Python311\\Lib\\site-packages\\pyee\\base.py\", line 169, in _emit_handle_potential_error\n    raise error\n  File \"C:\\Users\\Administrator\\Automation\\Tests\\test_AddMoney.py\", line 34, in on_response\n    result = await response.json()\n             ^^^^^^^^^^^^^^^^^^^^^\n  File \"C:\\Users\\Administrator\\AppData\\Local\\Programs\\Python\\Python311\\Lib\\site-packages\\playwright\\async_api\\_generated.py\", line 636, in json\n    return mapping.from_maybe_impl(await self._impl_obj.json())\n                                   ^^^^^^^^^^^^^^^^^^^^^^^^^^^\n  File \"C:\\Users\\Administrator\\AppData\\Local\\Programs\\Python\\Python311\\Lib\\site-packages\\playwright\\_impl\\_network.py\", line 590, in json\n    return json.loads(await self.text())\n           ^^^^^^^^^^^^^^^^^^^^^^^^^^^^^\n  File \"C:\\Users\\Administrator\\AppData\\Local\\Programs\\Python\\Python311\\Lib\\json\\__init__.py\", line 346, in loads\n    return _default_decoder.decode(s)\n           ^^^^^^^^^^^^^^^^^^^^^^^^^^\n  File \"C:\\Users\\Administrator\\AppData\\Local\\Programs\\Python\\Python311\\Lib\\json\\decoder.py\", line 337, in decode\n    obj, end = self.raw_decode(s, idx=_w(s, 0).end())\n               ^^^^^^^^^^^^^^^^^^^^^^^^^^^^^^^^^^^^^^\n  File \"C:\\Users\\Administrator\\AppData\\Local\\Programs\\Python\\Python311\\Lib\\json\\decoder.py\", line 355, in raw_decode\n    raise JSONDecodeError(\"Expecting value\", s, err.value) from None\njson.decoder.JSONDecodeError: Expecting value: line 1 column 1 (char 0)", "stack_info": null, "lineno": 1757, "funcName": "default_exception_handler", "created": 1720632081.8038585, "msecs": 803.0, "relativeCreated": 26689.6231174469, "thread": 5872, "threadName": "MainThread", "processName": "MainProcess", "process": 8348}], "longrepr": "page = <Page url='https://okoora-qa-front2023.azurewebsites.net/activate'>\nget_url = {'db_schem': 'ofakimdb', 'mail': 'jipop81748@in2reach.com', 'password': 'Okoora2!', 'url': 'https://okoora-qa-front2023.azurewebsites.net/login', ...}\n\n    @pytest.mark.regression\n    @pytest.mark.asyncio(scope='session')\n    @pytest.mark.qa\n    async def test_add_money(page,get_url):\n        user_data = get_url\n        url = user_data['url']\n        user_mail = user_data['mail']\n        password = user_data['password']\n        start = time.perf_counter()\n    \n        async def on_chooser(file_chooser):\n            await file_chooser.set_files(\"Upload.pdf\")\n            print(\"File uploaded\")\n    \n        async def on_response(response):\n            try:\n                if \"BalanceList\" in response.url:\n                    print(\"Waiting for response...\")\n                    result = await asyncio.wait_for(response.json(), timeout=5.0)\n                    print(\"Response received.\")\n            except asyncio.TimeoutError:\n                print(\"Response took more than 5 seconds.\")\n            if response.status != 200:\n                if response.status == 500:\n                    result = await response.json()\n                    raise Exception(response.url, response.status, json.dumps(result, indent=2))\n                result = await response.json()\n                print(response.url, response.status, json.dumps(result, indent=2))\n    \n        async def on_load(load):\n            print(load)\n    \n        async for page in page:\n            await page.goto(url)\n            page.on(\"filechooser\", on_chooser)\n            page.on(\"response\", on_response)\n            page.on(\"load\", on_load)\n    \n            await page.goto(url, wait_until=\"load\")\n            await page.locator(\"//input[@name='username']\").type(user_mail)\n            await page.locator(\"//input[@name='password']\").fill(password)\n            await page.get_by_role(\"button\", name=\"Log In \").click()\n>           await page.get_by_text(\"Settings\").click()\n\ntest_AddMoney.py:50: \n_ _ _ _ _ _ _ _ _ _ _ _ _ _ _ _ _ _ _ _ _ _ _ _ _ _ _ _ _ _ _ _ _ _ _ _ _ _ _ _\n..\\..\\AppData\\Local\\Programs\\Python\\Python311\\Lib\\site-packages\\playwright\\async_api\\_generated.py:15706: in click\n    await self._impl_obj.click(\n..\\..\\AppData\\Local\\Programs\\Python\\Python311\\Lib\\site-packages\\playwright\\_impl\\_locator.py:159: in click\n    return await self._frame.click(self._selector, strict=True, **params)\n..\\..\\AppData\\Local\\Programs\\Python\\Python311\\Lib\\site-packages\\playwright\\_impl\\_frame.py:484: in click\n    await self._channel.send(\"click\", locals_to_params(locals()))\n..\\..\\AppData\\Local\\Programs\\Python\\Python311\\Lib\\site-packages\\playwright\\_impl\\_connection.py:62: in send\n    return await self._connection.wrap_api_call(\n..\\..\\AppData\\Local\\Programs\\Python\\Python311\\Lib\\site-packages\\playwright\\_impl\\_connection.py:492: in wrap_api_call\n    return await cb()\n_ _ _ _ _ _ _ _ _ _ _ _ _ _ _ _ _ _ _ _ _ _ _ _ _ _ _ _ _ _ _ _ _ _ _ _ _ _ _ _\n\nself = <playwright._impl._connection.Channel object at 0x0000024FF20AC450>\nmethod = 'click'\nparams = {'selector': 'internal:text=\"Settings\"i', 'strict': True}\nreturn_as_dict = False\n\n    async def inner_send(\n        self, method: str, params: Optional[Dict], return_as_dict: bool\n    ) -> Any:\n        if params is None:\n            params = {}\n        callback = self._connection._send_message_to_server(\n            self._object, method, params\n        )\n        if self._connection._error:\n            error = self._connection._error\n            self._connection._error = None\n            raise error\n        done, _ = await asyncio.wait(\n            {\n                self._connection._transport.on_error_future,\n                callback.future,\n            },\n            return_when=asyncio.FIRST_COMPLETED,\n        )\n        if not callback.future.done():\n            callback.future.cancel()\n>       result = next(iter(done)).result()\nE       playwright._impl._errors.TimeoutError: Timeout 30000ms exceeded.\n\n..\\..\\AppData\\Local\\Programs\\Python\\Python311\\Lib\\site-packages\\playwright\\_impl\\_connection.py:100: TimeoutError"}, "teardown": {"duration": 0.0016336999833583832, "outcome": "passed"}}], "warnings": [{"message": "There is no current event loop", "category": "DeprecationWarning", "when": "runtest", "filename": "C:\\Users\\Administrator\\AppData\\Local\\Programs\\Python\\Python311\\Lib\\site-packages\\pytest_asyncio\\plugin.py", "lineno": 894}, {"message": "There is no current event loop", "category": "DeprecationWarning", "when": "runtest", "filename": "C:\\Users\\Administrator\\AppData\\Local\\Programs\\Python\\Python311\\Lib\\site-packages\\pytest_asyncio\\plugin.py", "lineno": 676}]}