{"created": 1721907868.626376, "duration": 28.631611585617065, "exitcode": 0, "root": "C:\\Users\\Administrator\\Automation\\Tests", "environment": {}, "summary": {"passed": 1, "total": 1, "collected": 1}, "collectors": [{"nodeid": "", "outcome": "passed", "result": [{"nodeid": "test_TravelCash.py", "type": "Module"}]}, {"nodeid": "test_TravelCash.py", "outcome": "passed", "result": [{"nodeid": "test_TravelCash.py::test_travel_cash", "type": "Coroutine", "lineno": 5}]}], "tests": [{"nodeid": "test_TravelCash.py::test_travel_cash", "lineno": 5, "outcome": "passed", "keywords": ["test_travel_cash", "regression", "asyncio", "pytestmark", "test_TravelCash.py", "__init__.py", "Tests"], "setup": {"duration": 0.004141499288380146, "outcome": "passed"}, "call": {"duration": 28.56949539948255, "outcome": "passed", "stdout": "<Page url='https://demo2.okoora.com/login'>\nhttps://okoora-demo-api2023.azurewebsites.net/api/Authentication/RefreshToken?refreshToken=undefined 400 {\n  \"apiErrorCode\": 1500,\n  \"apiErrorMessage\": [\n    \"The value 'undefined' is not valid.\"\n  ]\n}\nWaiting for response...\nResponse received.\nWaiting for response...\nResponse received.\nWaiting for response...\nResponse received.\nWaiting for response...\nResponse received.\n", "log": [{"name": "asyncio", "msg": "Exception in callback AsyncIOEventEmitter._emit_run.<locals>.callback(<Task finishe... 1 (char 0)')>) at C:\\Users\\Administrator\\AppData\\Local\\Programs\\Python\\Python311\\Lib\\site-packages\\pyee\\asyncio.py:69\nhandle: <Handle AsyncIOEventEmitter._emit_run.<locals>.callback(<Task finishe... 1 (char 0)')>) at C:\\Users\\Administrator\\AppData\\Local\\Programs\\Python\\Python311\\Lib\\site-packages\\pyee\\asyncio.py:69>", "args": null, "levelname": "ERROR", "levelno": 40, "pathname": "C:\\Users\\Administrator\\AppData\\Local\\Programs\\Python\\Python311\\Lib\\asyncio\\base_events.py", "filename": "base_events.py", "module": "base_events", "exc_info": null, "exc_text": "Traceback (most recent call last):\n  File \"C:\\Users\\Administrator\\AppData\\Local\\Programs\\Python\\Python311\\Lib\\asyncio\\events.py\", line 80, in _run\n    self._context.run(self._callback, *self._args)\n  File \"C:\\Users\\Administrator\\AppData\\Local\\Programs\\Python\\Python311\\Lib\\site-packages\\pyee\\asyncio.py\", line 77, in callback\n    self.emit(\"error\", exc)\n  File \"C:\\Users\\Administrator\\AppData\\Local\\Programs\\Python\\Python311\\Lib\\site-packages\\pyee\\base.py\", line 211, in emit\n    self._emit_handle_potential_error(event, args[0] if args else None)\n  File \"C:\\Users\\Administrator\\AppData\\Local\\Programs\\Python\\Python311\\Lib\\site-packages\\pyee\\base.py\", line 169, in _emit_handle_potential_error\n    raise error\n  File \"C:\\Users\\Administrator\\Automation\\Tests\\test_TravelCash.py\", line 38, in on_response\n    result = await response.json()\n             ^^^^^^^^^^^^^^^^^^^^^\n  File \"C:\\Users\\Administrator\\AppData\\Local\\Programs\\Python\\Python311\\Lib\\site-packages\\playwright\\async_api\\_generated.py\", line 636, in json\n    return mapping.from_maybe_impl(await self._impl_obj.json())\n                                   ^^^^^^^^^^^^^^^^^^^^^^^^^^^\n  File \"C:\\Users\\Administrator\\AppData\\Local\\Programs\\Python\\Python311\\Lib\\site-packages\\playwright\\_impl\\_network.py\", line 590, in json\n    return json.loads(await self.text())\n           ^^^^^^^^^^^^^^^^^^^^^^^^^^^^^\n  File \"C:\\Users\\Administrator\\AppData\\Local\\Programs\\Python\\Python311\\Lib\\json\\__init__.py\", line 346, in loads\n    return _default_decoder.decode(s)\n           ^^^^^^^^^^^^^^^^^^^^^^^^^^\n  File \"C:\\Users\\Administrator\\AppData\\Local\\Programs\\Python\\Python311\\Lib\\json\\decoder.py\", line 337, in decode\n    obj, end = self.raw_decode(s, idx=_w(s, 0).end())\n               ^^^^^^^^^^^^^^^^^^^^^^^^^^^^^^^^^^^^^^\n  File \"C:\\Users\\Administrator\\AppData\\Local\\Programs\\Python\\Python311\\Lib\\json\\decoder.py\", line 355, in raw_decode\n    raise JSONDecodeError(\"Expecting value\", s, err.value) from None\njson.decoder.JSONDecodeError: Expecting value: line 1 column 1 (char 0)", "stack_info": null, "lineno": 1757, "funcName": "default_exception_handler", "created": 1721907851.7859561, "msecs": 785.0, "relativeCreated": 13587.883472442627, "thread": 3280, "threadName": "MainThread", "processName": "MainProcess", "process": 1396}, {"name": "asyncio", "msg": "Exception in callback AsyncIOEventEmitter._emit_run.<locals>.callback(<Task finishe... 1 (char 0)')>) at C:\\Users\\Administrator\\AppData\\Local\\Programs\\Python\\Python311\\Lib\\site-packages\\pyee\\asyncio.py:69\nhandle: <Handle AsyncIOEventEmitter._emit_run.<locals>.callback(<Task finishe... 1 (char 0)')>) at C:\\Users\\Administrator\\AppData\\Local\\Programs\\Python\\Python311\\Lib\\site-packages\\pyee\\asyncio.py:69>", "args": null, "levelname": "ERROR", "levelno": 40, "pathname": "C:\\Users\\Administrator\\AppData\\Local\\Programs\\Python\\Python311\\Lib\\asyncio\\base_events.py", "filename": "base_events.py", "module": "base_events", "exc_info": null, "exc_text": "Traceback (most recent call last):\n  File \"C:\\Users\\Administrator\\AppData\\Local\\Programs\\Python\\Python311\\Lib\\asyncio\\events.py\", line 80, in _run\n    self._context.run(self._callback, *self._args)\n  File \"C:\\Users\\Administrator\\AppData\\Local\\Programs\\Python\\Python311\\Lib\\site-packages\\pyee\\asyncio.py\", line 77, in callback\n    self.emit(\"error\", exc)\n  File \"C:\\Users\\Administrator\\AppData\\Local\\Programs\\Python\\Python311\\Lib\\site-packages\\pyee\\base.py\", line 211, in emit\n    self._emit_handle_potential_error(event, args[0] if args else None)\n  File \"C:\\Users\\Administrator\\AppData\\Local\\Programs\\Python\\Python311\\Lib\\site-packages\\pyee\\base.py\", line 169, in _emit_handle_potential_error\n    raise error\n  File \"C:\\Users\\Administrator\\Automation\\Tests\\test_TravelCash.py\", line 38, in on_response\n    result = await response.json()\n             ^^^^^^^^^^^^^^^^^^^^^\n  File \"C:\\Users\\Administrator\\AppData\\Local\\Programs\\Python\\Python311\\Lib\\site-packages\\playwright\\async_api\\_generated.py\", line 636, in json\n    return mapping.from_maybe_impl(await self._impl_obj.json())\n                                   ^^^^^^^^^^^^^^^^^^^^^^^^^^^\n  File \"C:\\Users\\Administrator\\AppData\\Local\\Programs\\Python\\Python311\\Lib\\site-packages\\playwright\\_impl\\_network.py\", line 590, in json\n    return json.loads(await self.text())\n           ^^^^^^^^^^^^^^^^^^^^^^^^^^^^^\n  File \"C:\\Users\\Administrator\\AppData\\Local\\Programs\\Python\\Python311\\Lib\\json\\__init__.py\", line 346, in loads\n    return _default_decoder.decode(s)\n           ^^^^^^^^^^^^^^^^^^^^^^^^^^\n  File \"C:\\Users\\Administrator\\AppData\\Local\\Programs\\Python\\Python311\\Lib\\json\\decoder.py\", line 337, in decode\n    obj, end = self.raw_decode(s, idx=_w(s, 0).end())\n               ^^^^^^^^^^^^^^^^^^^^^^^^^^^^^^^^^^^^^^\n  File \"C:\\Users\\Administrator\\AppData\\Local\\Programs\\Python\\Python311\\Lib\\json\\decoder.py\", line 355, in raw_decode\n    raise JSONDecodeError(\"Expecting value\", s, err.value) from None\njson.decoder.JSONDecodeError: Expecting value: line 1 column 1 (char 0)", "stack_info": null, "lineno": 1757, "funcName": "default_exception_handler", "created": 1721907851.8355086, "msecs": 835.0, "relativeCreated": 13637.435913085938, "thread": 3280, "threadName": "MainThread", "processName": "MainProcess", "process": 1396}, {"name": "asyncio", "msg": "Exception in callback AsyncIOEventEmitter._emit_run.<locals>.callback(<Task finishe... identifier')>) at C:\\Users\\Administrator\\AppData\\Local\\Programs\\Python\\Python311\\Lib\\site-packages\\pyee\\asyncio.py:69\nhandle: <Handle AsyncIOEventEmitter._emit_run.<locals>.callback(<Task finishe... identifier')>) at C:\\Users\\Administrator\\AppData\\Local\\Programs\\Python\\Python311\\Lib\\site-packages\\pyee\\asyncio.py:69>", "args": null, "levelname": "ERROR", "levelno": 40, "pathname": "C:\\Users\\Administrator\\AppData\\Local\\Programs\\Python\\Python311\\Lib\\asyncio\\base_events.py", "filename": "base_events.py", "module": "base_events", "exc_info": null, "exc_text": "Traceback (most recent call last):\n  File \"C:\\Users\\Administrator\\AppData\\Local\\Programs\\Python\\Python311\\Lib\\asyncio\\events.py\", line 80, in _run\n    self._context.run(self._callback, *self._args)\n  File \"C:\\Users\\Administrator\\AppData\\Local\\Programs\\Python\\Python311\\Lib\\site-packages\\pyee\\asyncio.py\", line 77, in callback\n    self.emit(\"error\", exc)\n  File \"C:\\Users\\Administrator\\AppData\\Local\\Programs\\Python\\Python311\\Lib\\site-packages\\pyee\\base.py\", line 211, in emit\n    self._emit_handle_potential_error(event, args[0] if args else None)\n  File \"C:\\Users\\Administrator\\AppData\\Local\\Programs\\Python\\Python311\\Lib\\site-packages\\pyee\\base.py\", line 169, in _emit_handle_potential_error\n    raise error\n  File \"C:\\Users\\Administrator\\Automation\\Tests\\test_TravelCash.py\", line 38, in on_response\n    result = await response.json()\n             ^^^^^^^^^^^^^^^^^^^^^\n  File \"C:\\Users\\Administrator\\AppData\\Local\\Programs\\Python\\Python311\\Lib\\site-packages\\playwright\\async_api\\_generated.py\", line 636, in json\n    return mapping.from_maybe_impl(await self._impl_obj.json())\n                                   ^^^^^^^^^^^^^^^^^^^^^^^^^^^\n  File \"C:\\Users\\Administrator\\AppData\\Local\\Programs\\Python\\Python311\\Lib\\site-packages\\playwright\\_impl\\_network.py\", line 590, in json\n    return json.loads(await self.text())\n                      ^^^^^^^^^^^^^^^^^\n  File \"C:\\Users\\Administrator\\AppData\\Local\\Programs\\Python\\Python311\\Lib\\site-packages\\playwright\\_impl\\_network.py\", line 586, in text\n    content = await self.body()\n              ^^^^^^^^^^^^^^^^^\n  File \"C:\\Users\\Administrator\\AppData\\Local\\Programs\\Python\\Python311\\Lib\\site-packages\\playwright\\_impl\\_network.py\", line 582, in body\n    binary = await self._channel.send(\"body\")\n             ^^^^^^^^^^^^^^^^^^^^^^^^^^^^^^^^\n  File \"C:\\Users\\Administrator\\AppData\\Local\\Programs\\Python\\Python311\\Lib\\site-packages\\playwright\\_impl\\_connection.py\", line 62, in send\n    return await self._connection.wrap_api_call(\n           ^^^^^^^^^^^^^^^^^^^^^^^^^^^^^^^^^^^^^\n  File \"C:\\Users\\Administrator\\AppData\\Local\\Programs\\Python\\Python311\\Lib\\site-packages\\playwright\\_impl\\_connection.py\", line 492, in wrap_api_call\n    return await cb()\n           ^^^^^^^^^^\n  File \"C:\\Users\\Administrator\\AppData\\Local\\Programs\\Python\\Python311\\Lib\\site-packages\\playwright\\_impl\\_connection.py\", line 100, in inner_send\n    result = next(iter(done)).result()\n             ^^^^^^^^^^^^^^^^^^^^^^^^^\nplaywright._impl._errors.Error: Protocol error (Network.getResponseBody): No data found for resource with given identifier", "stack_info": null, "lineno": 1757, "funcName": "default_exception_handler", "created": 1721907855.5751333, "msecs": 575.0, "relativeCreated": 17377.060651779175, "thread": 3280, "threadName": "MainThread", "processName": "MainProcess", "process": 1396}, {"name": "asyncio", "msg": "Exception in callback AsyncIOEventEmitter._emit_run.<locals>.callback(<Task finishe... identifier')>) at C:\\Users\\Administrator\\AppData\\Local\\Programs\\Python\\Python311\\Lib\\site-packages\\pyee\\asyncio.py:69\nhandle: <Handle AsyncIOEventEmitter._emit_run.<locals>.callback(<Task finishe... identifier')>) at C:\\Users\\Administrator\\AppData\\Local\\Programs\\Python\\Python311\\Lib\\site-packages\\pyee\\asyncio.py:69>", "args": null, "levelname": "ERROR", "levelno": 40, "pathname": "C:\\Users\\Administrator\\AppData\\Local\\Programs\\Python\\Python311\\Lib\\asyncio\\base_events.py", "filename": "base_events.py", "module": "base_events", "exc_info": null, "exc_text": "Traceback (most recent call last):\n  File \"C:\\Users\\Administrator\\AppData\\Local\\Programs\\Python\\Python311\\Lib\\asyncio\\events.py\", line 80, in _run\n    self._context.run(self._callback, *self._args)\n  File \"C:\\Users\\Administrator\\AppData\\Local\\Programs\\Python\\Python311\\Lib\\site-packages\\pyee\\asyncio.py\", line 77, in callback\n    self.emit(\"error\", exc)\n  File \"C:\\Users\\Administrator\\AppData\\Local\\Programs\\Python\\Python311\\Lib\\site-packages\\pyee\\base.py\", line 211, in emit\n    self._emit_handle_potential_error(event, args[0] if args else None)\n  File \"C:\\Users\\Administrator\\AppData\\Local\\Programs\\Python\\Python311\\Lib\\site-packages\\pyee\\base.py\", line 169, in _emit_handle_potential_error\n    raise error\n  File \"C:\\Users\\Administrator\\Automation\\Tests\\test_TravelCash.py\", line 38, in on_response\n    result = await response.json()\n             ^^^^^^^^^^^^^^^^^^^^^\n  File \"C:\\Users\\Administrator\\AppData\\Local\\Programs\\Python\\Python311\\Lib\\site-packages\\playwright\\async_api\\_generated.py\", line 636, in json\n    return mapping.from_maybe_impl(await self._impl_obj.json())\n                                   ^^^^^^^^^^^^^^^^^^^^^^^^^^^\n  File \"C:\\Users\\Administrator\\AppData\\Local\\Programs\\Python\\Python311\\Lib\\site-packages\\playwright\\_impl\\_network.py\", line 590, in json\n    return json.loads(await self.text())\n                      ^^^^^^^^^^^^^^^^^\n  File \"C:\\Users\\Administrator\\AppData\\Local\\Programs\\Python\\Python311\\Lib\\site-packages\\playwright\\_impl\\_network.py\", line 586, in text\n    content = await self.body()\n              ^^^^^^^^^^^^^^^^^\n  File \"C:\\Users\\Administrator\\AppData\\Local\\Programs\\Python\\Python311\\Lib\\site-packages\\playwright\\_impl\\_network.py\", line 582, in body\n    binary = await self._channel.send(\"body\")\n             ^^^^^^^^^^^^^^^^^^^^^^^^^^^^^^^^\n  File \"C:\\Users\\Administrator\\AppData\\Local\\Programs\\Python\\Python311\\Lib\\site-packages\\playwright\\_impl\\_connection.py\", line 62, in send\n    return await self._connection.wrap_api_call(\n           ^^^^^^^^^^^^^^^^^^^^^^^^^^^^^^^^^^^^^\n  File \"C:\\Users\\Administrator\\AppData\\Local\\Programs\\Python\\Python311\\Lib\\site-packages\\playwright\\_impl\\_connection.py\", line 492, in wrap_api_call\n    return await cb()\n           ^^^^^^^^^^\n  File \"C:\\Users\\Administrator\\AppData\\Local\\Programs\\Python\\Python311\\Lib\\site-packages\\playwright\\_impl\\_connection.py\", line 100, in inner_send\n    result = next(iter(done)).result()\n             ^^^^^^^^^^^^^^^^^^^^^^^^^\nplaywright._impl._errors.Error: Protocol error (Network.getResponseBody): No data found for resource with given identifier", "stack_info": null, "lineno": 1757, "funcName": "default_exception_handler", "created": 1721907866.292708, "msecs": 292.0, "relativeCreated": 28094.635248184204, "thread": 3280, "threadName": "MainThread", "processName": "MainProcess", "process": 1396}, {"name": "asyncio", "msg": "Exception in callback AsyncIOEventEmitter._emit_run.<locals>.callback(<Task finishe... identifier')>) at C:\\Users\\Administrator\\AppData\\Local\\Programs\\Python\\Python311\\Lib\\site-packages\\pyee\\asyncio.py:69\nhandle: <Handle AsyncIOEventEmitter._emit_run.<locals>.callback(<Task finishe... identifier')>) at C:\\Users\\Administrator\\AppData\\Local\\Programs\\Python\\Python311\\Lib\\site-packages\\pyee\\asyncio.py:69>", "args": null, "levelname": "ERROR", "levelno": 40, "pathname": "C:\\Users\\Administrator\\AppData\\Local\\Programs\\Python\\Python311\\Lib\\asyncio\\base_events.py", "filename": "base_events.py", "module": "base_events", "exc_info": null, "exc_text": "Traceback (most recent call last):\n  File \"C:\\Users\\Administrator\\AppData\\Local\\Programs\\Python\\Python311\\Lib\\asyncio\\events.py\", line 80, in _run\n    self._context.run(self._callback, *self._args)\n  File \"C:\\Users\\Administrator\\AppData\\Local\\Programs\\Python\\Python311\\Lib\\site-packages\\pyee\\asyncio.py\", line 77, in callback\n    self.emit(\"error\", exc)\n  File \"C:\\Users\\Administrator\\AppData\\Local\\Programs\\Python\\Python311\\Lib\\site-packages\\pyee\\base.py\", line 211, in emit\n    self._emit_handle_potential_error(event, args[0] if args else None)\n  File \"C:\\Users\\Administrator\\AppData\\Local\\Programs\\Python\\Python311\\Lib\\site-packages\\pyee\\base.py\", line 169, in _emit_handle_potential_error\n    raise error\n  File \"C:\\Users\\Administrator\\Automation\\Tests\\test_TravelCash.py\", line 38, in on_response\n    result = await response.json()\n             ^^^^^^^^^^^^^^^^^^^^^\n  File \"C:\\Users\\Administrator\\AppData\\Local\\Programs\\Python\\Python311\\Lib\\site-packages\\playwright\\async_api\\_generated.py\", line 636, in json\n    return mapping.from_maybe_impl(await self._impl_obj.json())\n                                   ^^^^^^^^^^^^^^^^^^^^^^^^^^^\n  File \"C:\\Users\\Administrator\\AppData\\Local\\Programs\\Python\\Python311\\Lib\\site-packages\\playwright\\_impl\\_network.py\", line 590, in json\n    return json.loads(await self.text())\n                      ^^^^^^^^^^^^^^^^^\n  File \"C:\\Users\\Administrator\\AppData\\Local\\Programs\\Python\\Python311\\Lib\\site-packages\\playwright\\_impl\\_network.py\", line 586, in text\n    content = await self.body()\n              ^^^^^^^^^^^^^^^^^\n  File \"C:\\Users\\Administrator\\AppData\\Local\\Programs\\Python\\Python311\\Lib\\site-packages\\playwright\\_impl\\_network.py\", line 582, in body\n    binary = await self._channel.send(\"body\")\n             ^^^^^^^^^^^^^^^^^^^^^^^^^^^^^^^^\n  File \"C:\\Users\\Administrator\\AppData\\Local\\Programs\\Python\\Python311\\Lib\\site-packages\\playwright\\_impl\\_connection.py\", line 62, in send\n    return await self._connection.wrap_api_call(\n           ^^^^^^^^^^^^^^^^^^^^^^^^^^^^^^^^^^^^^\n  File \"C:\\Users\\Administrator\\AppData\\Local\\Programs\\Python\\Python311\\Lib\\site-packages\\playwright\\_impl\\_connection.py\", line 492, in wrap_api_call\n    return await cb()\n           ^^^^^^^^^^\n  File \"C:\\Users\\Administrator\\AppData\\Local\\Programs\\Python\\Python311\\Lib\\site-packages\\playwright\\_impl\\_connection.py\", line 100, in inner_send\n    result = next(iter(done)).result()\n             ^^^^^^^^^^^^^^^^^^^^^^^^^\nplaywright._impl._errors.Error: Protocol error (Network.getResponseBody): No data found for resource with given identifier", "stack_info": null, "lineno": 1757, "funcName": "default_exception_handler", "created": 1721907867.3843763, "msecs": 384.0, "relativeCreated": 29186.30361557007, "thread": 3280, "threadName": "MainThread", "processName": "MainProcess", "process": 1396}]}, "teardown": {"duration": 0.001269499771296978, "outcome": "passed"}}], "warnings": [{"message": "There is no current event loop", "category": "DeprecationWarning", "when": "runtest", "filename": "C:\\Users\\Administrator\\AppData\\Local\\Programs\\Python\\Python311\\Lib\\site-packages\\pytest_asyncio\\plugin.py", "lineno": 894}, {"message": "There is no current event loop", "category": "DeprecationWarning", "when": "runtest", "filename": "C:\\Users\\Administrator\\AppData\\Local\\Programs\\Python\\Python311\\Lib\\site-packages\\pytest_asyncio\\plugin.py", "lineno": 676}]}