{"created": 1720676474.6069176, "duration": 19.710195779800415, "exitcode": 0, "root": "C:\\Users\\Administrator\\Automation\\Tests", "environment": {}, "summary": {"passed": 1, "total": 1, "collected": 1}, "collectors": [{"nodeid": "", "outcome": "passed", "result": [{"nodeid": "test_AddMoney.py", "type": "Module"}]}, {"nodeid": "test_AddMoney.py", "outcome": "passed", "result": [{"nodeid": "test_AddMoney.py::test_add_money", "type": "Coroutine", "lineno": 7}]}], "tests": [{"nodeid": "test_AddMoney.py::test_add_money", "lineno": 7, "outcome": "passed", "keywords": ["test_add_money", "qa", "asyncio", "regression", "pytestmark", "test_AddMoney.py", "__init__.py", "Tests"], "setup": {"duration": 0.003918500151485205, "outcome": "passed"}, "call": {"duration": 19.676058399956673, "outcome": "passed", "stdout": "<Page url='https://okoora-qa-front2023.azurewebsites.net/login'>\nhttps://okoora-qa-api2023.azurewebsites.net/api/Authentication/RefreshToken?refreshToken=undefined 400 {\n  \"apiErrorCode\": 1500,\n  \"apiErrorMessage\": [\n    \"The value 'undefined' is not valid.\"\n  ]\n}\nWaiting for response...\nResponse received.\nWaiting for response...\nResponse received.\nhttps://okoora-qa-api2023.azurewebsites.net/api/Balances/DepositRegular?Currency=ILS&Amount=10,000&OkooraBankId=2&BeneficiaryId=2de9ce1d-4ec3-42fb-9eaf-11d56d44a326&TransferType=3&TransferAt= 201 \"e1138dff-8227-4d81-a874-61f31a221c93\"\n", "log": [{"name": "asyncio", "msg": "Exception in callback AsyncIOEventEmitter._emit_run.<locals>.callback(<Task finishe... 1 (char 0)')>) at C:\\Users\\Administrator\\AppData\\Local\\Programs\\Python\\Python311\\Lib\\site-packages\\pyee\\asyncio.py:69\nhandle: <Handle AsyncIOEventEmitter._emit_run.<locals>.callback(<Task finishe... 1 (char 0)')>) at C:\\Users\\Administrator\\AppData\\Local\\Programs\\Python\\Python311\\Lib\\site-packages\\pyee\\asyncio.py:69>", "args": null, "levelname": "ERROR", "levelno": 40, "pathname": "C:\\Users\\Administrator\\AppData\\Local\\Programs\\Python\\Python311\\Lib\\asyncio\\base_events.py", "filename": "base_events.py", "module": "base_events", "exc_info": null, "exc_text": "Traceback (most recent call last):\n  File \"C:\\Users\\Administrator\\AppData\\Local\\Programs\\Python\\Python311\\Lib\\asyncio\\events.py\", line 80, in _run\n    self._context.run(self._callback, *self._args)\n  File \"C:\\Users\\Administrator\\AppData\\Local\\Programs\\Python\\Python311\\Lib\\site-packages\\pyee\\asyncio.py\", line 77, in callback\n    self.emit(\"error\", exc)\n  File \"C:\\Users\\Administrator\\AppData\\Local\\Programs\\Python\\Python311\\Lib\\site-packages\\pyee\\base.py\", line 211, in emit\n    self._emit_handle_potential_error(event, args[0] if args else None)\n  File \"C:\\Users\\Administrator\\AppData\\Local\\Programs\\Python\\Python311\\Lib\\site-packages\\pyee\\base.py\", line 169, in _emit_handle_potential_error\n    raise error\n  File \"C:\\Users\\Administrator\\Automation\\Tests\\test_AddMoney.py\", line 34, in on_response\n    result = await response.json()\n             ^^^^^^^^^^^^^^^^^^^^^\n  File \"C:\\Users\\Administrator\\AppData\\Local\\Programs\\Python\\Python311\\Lib\\site-packages\\playwright\\async_api\\_generated.py\", line 636, in json\n    return mapping.from_maybe_impl(await self._impl_obj.json())\n                                   ^^^^^^^^^^^^^^^^^^^^^^^^^^^\n  File \"C:\\Users\\Administrator\\AppData\\Local\\Programs\\Python\\Python311\\Lib\\site-packages\\playwright\\_impl\\_network.py\", line 590, in json\n    return json.loads(await self.text())\n           ^^^^^^^^^^^^^^^^^^^^^^^^^^^^^\n  File \"C:\\Users\\Administrator\\AppData\\Local\\Programs\\Python\\Python311\\Lib\\json\\__init__.py\", line 346, in loads\n    return _default_decoder.decode(s)\n           ^^^^^^^^^^^^^^^^^^^^^^^^^^\n  File \"C:\\Users\\Administrator\\AppData\\Local\\Programs\\Python\\Python311\\Lib\\json\\decoder.py\", line 337, in decode\n    obj, end = self.raw_decode(s, idx=_w(s, 0).end())\n               ^^^^^^^^^^^^^^^^^^^^^^^^^^^^^^^^^^^^^^\n  File \"C:\\Users\\Administrator\\AppData\\Local\\Programs\\Python\\Python311\\Lib\\json\\decoder.py\", line 355, in raw_decode\n    raise JSONDecodeError(\"Expecting value\", s, err.value) from None\njson.decoder.JSONDecodeError: Expecting value: line 1 column 1 (char 0)", "stack_info": null, "lineno": 1757, "funcName": "default_exception_handler", "created": 1720676460.601352, "msecs": 601.0, "relativeCreated": 6665.605068206787, "thread": 12476, "threadName": "MainThread", "processName": "MainProcess", "process": 4160}, {"name": "asyncio", "msg": "Exception in callback AsyncIOEventEmitter._emit_run.<locals>.callback(<Task finishe... 1 (char 0)')>) at C:\\Users\\Administrator\\AppData\\Local\\Programs\\Python\\Python311\\Lib\\site-packages\\pyee\\asyncio.py:69\nhandle: <Handle AsyncIOEventEmitter._emit_run.<locals>.callback(<Task finishe... 1 (char 0)')>) at C:\\Users\\Administrator\\AppData\\Local\\Programs\\Python\\Python311\\Lib\\site-packages\\pyee\\asyncio.py:69>", "args": null, "levelname": "ERROR", "levelno": 40, "pathname": "C:\\Users\\Administrator\\AppData\\Local\\Programs\\Python\\Python311\\Lib\\asyncio\\base_events.py", "filename": "base_events.py", "module": "base_events", "exc_info": null, "exc_text": "Traceback (most recent call last):\n  File \"C:\\Users\\Administrator\\AppData\\Local\\Programs\\Python\\Python311\\Lib\\asyncio\\events.py\", line 80, in _run\n    self._context.run(self._callback, *self._args)\n  File \"C:\\Users\\Administrator\\AppData\\Local\\Programs\\Python\\Python311\\Lib\\site-packages\\pyee\\asyncio.py\", line 77, in callback\n    self.emit(\"error\", exc)\n  File \"C:\\Users\\Administrator\\AppData\\Local\\Programs\\Python\\Python311\\Lib\\site-packages\\pyee\\base.py\", line 211, in emit\n    self._emit_handle_potential_error(event, args[0] if args else None)\n  File \"C:\\Users\\Administrator\\AppData\\Local\\Programs\\Python\\Python311\\Lib\\site-packages\\pyee\\base.py\", line 169, in _emit_handle_potential_error\n    raise error\n  File \"C:\\Users\\Administrator\\Automation\\Tests\\test_AddMoney.py\", line 34, in on_response\n    result = await response.json()\n             ^^^^^^^^^^^^^^^^^^^^^\n  File \"C:\\Users\\Administrator\\AppData\\Local\\Programs\\Python\\Python311\\Lib\\site-packages\\playwright\\async_api\\_generated.py\", line 636, in json\n    return mapping.from_maybe_impl(await self._impl_obj.json())\n                                   ^^^^^^^^^^^^^^^^^^^^^^^^^^^\n  File \"C:\\Users\\Administrator\\AppData\\Local\\Programs\\Python\\Python311\\Lib\\site-packages\\playwright\\_impl\\_network.py\", line 590, in json\n    return json.loads(await self.text())\n           ^^^^^^^^^^^^^^^^^^^^^^^^^^^^^\n  File \"C:\\Users\\Administrator\\AppData\\Local\\Programs\\Python\\Python311\\Lib\\json\\__init__.py\", line 346, in loads\n    return _default_decoder.decode(s)\n           ^^^^^^^^^^^^^^^^^^^^^^^^^^\n  File \"C:\\Users\\Administrator\\AppData\\Local\\Programs\\Python\\Python311\\Lib\\json\\decoder.py\", line 337, in decode\n    obj, end = self.raw_decode(s, idx=_w(s, 0).end())\n               ^^^^^^^^^^^^^^^^^^^^^^^^^^^^^^^^^^^^^^\n  File \"C:\\Users\\Administrator\\AppData\\Local\\Programs\\Python\\Python311\\Lib\\json\\decoder.py\", line 355, in raw_decode\n    raise JSONDecodeError(\"Expecting value\", s, err.value) from None\njson.decoder.JSONDecodeError: Expecting value: line 1 column 1 (char 0)", "stack_info": null, "lineno": 1757, "funcName": "default_exception_handler", "created": 1720676460.6058733, "msecs": 605.0, "relativeCreated": 6670.126438140869, "thread": 12476, "threadName": "MainThread", "processName": "MainProcess", "process": 4160}, {"name": "asyncio", "msg": "Exception in callback AsyncIOEventEmitter._emit_run.<locals>.callback(<Task finishe... identifier')>) at C:\\Users\\Administrator\\AppData\\Local\\Programs\\Python\\Python311\\Lib\\site-packages\\pyee\\asyncio.py:69\nhandle: <Handle AsyncIOEventEmitter._emit_run.<locals>.callback(<Task finishe... identifier')>) at C:\\Users\\Administrator\\AppData\\Local\\Programs\\Python\\Python311\\Lib\\site-packages\\pyee\\asyncio.py:69>", "args": null, "levelname": "ERROR", "levelno": 40, "pathname": "C:\\Users\\Administrator\\AppData\\Local\\Programs\\Python\\Python311\\Lib\\asyncio\\base_events.py", "filename": "base_events.py", "module": "base_events", "exc_info": null, "exc_text": "Traceback (most recent call last):\n  File \"C:\\Users\\Administrator\\AppData\\Local\\Programs\\Python\\Python311\\Lib\\asyncio\\events.py\", line 80, in _run\n    self._context.run(self._callback, *self._args)\n  File \"C:\\Users\\Administrator\\AppData\\Local\\Programs\\Python\\Python311\\Lib\\site-packages\\pyee\\asyncio.py\", line 77, in callback\n    self.emit(\"error\", exc)\n  File \"C:\\Users\\Administrator\\AppData\\Local\\Programs\\Python\\Python311\\Lib\\site-packages\\pyee\\base.py\", line 211, in emit\n    self._emit_handle_potential_error(event, args[0] if args else None)\n  File \"C:\\Users\\Administrator\\AppData\\Local\\Programs\\Python\\Python311\\Lib\\site-packages\\pyee\\base.py\", line 169, in _emit_handle_potential_error\n    raise error\n  File \"C:\\Users\\Administrator\\Automation\\Tests\\test_AddMoney.py\", line 34, in on_response\n    result = await response.json()\n             ^^^^^^^^^^^^^^^^^^^^^\n  File \"C:\\Users\\Administrator\\AppData\\Local\\Programs\\Python\\Python311\\Lib\\site-packages\\playwright\\async_api\\_generated.py\", line 636, in json\n    return mapping.from_maybe_impl(await self._impl_obj.json())\n                                   ^^^^^^^^^^^^^^^^^^^^^^^^^^^\n  File \"C:\\Users\\Administrator\\AppData\\Local\\Programs\\Python\\Python311\\Lib\\site-packages\\playwright\\_impl\\_network.py\", line 590, in json\n    return json.loads(await self.text())\n                      ^^^^^^^^^^^^^^^^^\n  File \"C:\\Users\\Administrator\\AppData\\Local\\Programs\\Python\\Python311\\Lib\\site-packages\\playwright\\_impl\\_network.py\", line 586, in text\n    content = await self.body()\n              ^^^^^^^^^^^^^^^^^\n  File \"C:\\Users\\Administrator\\AppData\\Local\\Programs\\Python\\Python311\\Lib\\site-packages\\playwright\\_impl\\_network.py\", line 582, in body\n    binary = await self._channel.send(\"body\")\n             ^^^^^^^^^^^^^^^^^^^^^^^^^^^^^^^^\n  File \"C:\\Users\\Administrator\\AppData\\Local\\Programs\\Python\\Python311\\Lib\\site-packages\\playwright\\_impl\\_connection.py\", line 62, in send\n    return await self._connection.wrap_api_call(\n           ^^^^^^^^^^^^^^^^^^^^^^^^^^^^^^^^^^^^^\n  File \"C:\\Users\\Administrator\\AppData\\Local\\Programs\\Python\\Python311\\Lib\\site-packages\\playwright\\_impl\\_connection.py\", line 492, in wrap_api_call\n    return await cb()\n           ^^^^^^^^^^\n  File \"C:\\Users\\Administrator\\AppData\\Local\\Programs\\Python\\Python311\\Lib\\site-packages\\playwright\\_impl\\_connection.py\", line 100, in inner_send\n    result = next(iter(done)).result()\n             ^^^^^^^^^^^^^^^^^^^^^^^^^\nplaywright._impl._errors.Error: Protocol error (Network.getResponseBody): No data found for resource with given identifier", "stack_info": null, "lineno": 1757, "funcName": "default_exception_handler", "created": 1720676465.2863824, "msecs": 286.0, "relativeCreated": 11350.635528564453, "thread": 12476, "threadName": "MainThread", "processName": "MainProcess", "process": 4160}]}, "teardown": {"duration": 0.0010723997838795185, "outcome": "passed"}}], "warnings": [{"message": "There is no current event loop", "category": "DeprecationWarning", "when": "runtest", "filename": "C:\\Users\\Administrator\\AppData\\Local\\Programs\\Python\\Python311\\Lib\\site-packages\\pytest_asyncio\\plugin.py", "lineno": 894}, {"message": "There is no current event loop", "category": "DeprecationWarning", "when": "runtest", "filename": "C:\\Users\\Administrator\\AppData\\Local\\Programs\\Python\\Python311\\Lib\\site-packages\\pytest_asyncio\\plugin.py", "lineno": 676}]}